{
 "cells": [
  {
   "cell_type": "markdown",
   "metadata": {},
   "source": [
    "# Structure Learning\n",
    "Defining the structure of a Bayesian Network (BN) model can be done based on machine learning, domain knowledge, or a combination of both, where experts and algorithms contribute as equal partners.\n",
    "\n",
    "Structure from Domain Knowledge\n",
    "We can manually define a structure model by specifying the relationships between different features."
   ]
  },
  {
   "cell_type": "code",
   "execution_count": 2,
   "metadata": {},
   "outputs": [
    {
     "name": "stdout",
     "output_type": "stream",
     "text": [
      "Defaulting to user installation because normal site-packages is not writeable\n",
      "Collecting causalnex\n",
      "  Using cached causalnex-0.12.1-py3-none-any.whl.metadata (7.8 kB)\n",
      "Requirement already satisfied: ipython>=8.10.0 in /home/tema/.local/lib/python3.10/site-packages (from causalnex) (8.25.0)\n",
      "Collecting networkx>=2.5 (from causalnex)\n",
      "  Using cached networkx-3.3-py3-none-any.whl.metadata (5.1 kB)\n",
      "Collecting numpy<1.24,>=1.14.2 (from causalnex)\n",
      "  Using cached numpy-1.23.5-cp310-cp310-manylinux_2_17_x86_64.manylinux2014_x86_64.whl.metadata (2.3 kB)\n",
      "Collecting pandas<2.0,>=1.0 (from causalnex)\n",
      "  Using cached pandas-1.5.3-cp310-cp310-manylinux_2_17_x86_64.manylinux2014_x86_64.whl.metadata (11 kB)\n",
      "\u001b[33mWARNING: Retrying (Retry(total=4, connect=None, read=None, redirect=None, status=None)) after connection broken by 'ReadTimeoutError(\"HTTPSConnectionPool(host='pypi.org', port=443): Read timed out. (read timeout=15)\")': /simple/pathos/\u001b[0m\u001b[33m\n",
      "\u001b[0m\u001b[33mWARNING: Retrying (Retry(total=3, connect=None, read=None, redirect=None, status=None)) after connection broken by 'ProtocolError('Connection aborted.', ConnectionResetError(104, 'Connection reset by peer'))': /simple/pathos/\u001b[0m\u001b[33m\n",
      "\u001b[0m\u001b[33mWARNING: Retrying (Retry(total=2, connect=None, read=None, redirect=None, status=None)) after connection broken by 'NewConnectionError('<pip._vendor.urllib3.connection.HTTPSConnection object at 0x7f59ead9db10>: Failed to establish a new connection: [Errno 101] Network is unreachable')': /simple/pathos/\u001b[0m\u001b[33m\n",
      "\u001b[0mCollecting pathos>=0.2.7 (from causalnex)\n",
      "  Using cached pathos-0.3.2-py3-none-any.whl.metadata (11 kB)\n",
      "Collecting pgmpy<0.1.20,>=0.1.14 (from causalnex)\n",
      "  Using cached pgmpy-0.1.19-py3-none-any.whl.metadata (6.3 kB)\n",
      "Collecting pyvis>=0.3.2 (from causalnex)\n",
      "  Downloading pyvis-0.3.2-py3-none-any.whl.metadata (1.7 kB)\n",
      "Requirement already satisfied: scipy>=1.7 in /usr/lib/python3/dist-packages (from causalnex) (1.11.4)\n",
      "Requirement already satisfied: setuptools>=65.5.1 in /usr/lib/python3/dist-packages (from causalnex) (68.1.2)\n",
      "Collecting torch>=1.7 (from causalnex)\n",
      "  Downloading torch-2.3.1-cp310-cp310-manylinux1_x86_64.whl.metadata (26 kB)\n",
      "Requirement already satisfied: wheel>=0.38.0 in /usr/lib/python3/dist-packages (from causalnex) (0.42.0)\n",
      "Collecting scikit-learn>=0.25.0 (from causalnex)\n",
      "  Downloading scikit_learn-1.5.0-cp310-cp310-manylinux_2_17_x86_64.manylinux2014_x86_64.whl.metadata (11 kB)\n",
      "Requirement already satisfied: decorator in /home/tema/.local/lib/python3.10/site-packages (from ipython>=8.10.0->causalnex) (5.1.1)\n",
      "Requirement already satisfied: jedi>=0.16 in /home/tema/.local/lib/python3.10/site-packages (from ipython>=8.10.0->causalnex) (0.19.1)\n",
      "Requirement already satisfied: matplotlib-inline in /home/tema/.local/lib/python3.10/site-packages (from ipython>=8.10.0->causalnex) (0.1.7)\n",
      "Requirement already satisfied: prompt-toolkit<3.1.0,>=3.0.41 in /home/tema/.local/lib/python3.10/site-packages (from ipython>=8.10.0->causalnex) (3.0.47)\n",
      "Requirement already satisfied: pygments>=2.4.0 in /home/tema/.local/lib/python3.10/site-packages (from ipython>=8.10.0->causalnex) (2.18.0)\n",
      "Requirement already satisfied: stack-data in /home/tema/.local/lib/python3.10/site-packages (from ipython>=8.10.0->causalnex) (0.6.3)\n",
      "Requirement already satisfied: traitlets>=5.13.0 in /home/tema/.local/lib/python3.10/site-packages (from ipython>=8.10.0->causalnex) (5.14.3)\n",
      "Requirement already satisfied: exceptiongroup in /home/tema/.local/lib/python3.10/site-packages (from ipython>=8.10.0->causalnex) (1.2.1)\n",
      "Requirement already satisfied: typing-extensions>=4.6 in /home/tema/.local/lib/python3.10/site-packages (from ipython>=8.10.0->causalnex) (4.12.2)\n",
      "Requirement already satisfied: pexpect>4.3 in /home/tema/.local/lib/python3.10/site-packages (from ipython>=8.10.0->causalnex) (4.9.0)\n",
      "Requirement already satisfied: python-dateutil>=2.8.1 in /home/tema/.local/lib/python3.10/site-packages (from pandas<2.0,>=1.0->causalnex) (2.9.0.post0)\n",
      "Requirement already satisfied: pytz>=2020.1 in /usr/lib/python3/dist-packages (from pandas<2.0,>=1.0->causalnex) (2024.1)\n",
      "Collecting ppft>=1.7.6.8 (from pathos>=0.2.7->causalnex)\n",
      "  Downloading ppft-1.7.6.8-py3-none-any.whl.metadata (12 kB)\n",
      "Collecting dill>=0.3.8 (from pathos>=0.2.7->causalnex)\n",
      "  Using cached dill-0.3.8-py3-none-any.whl.metadata (10 kB)\n",
      "Collecting pox>=0.3.4 (from pathos>=0.2.7->causalnex)\n",
      "  Downloading pox-0.3.4-py3-none-any.whl.metadata (8.0 kB)\n",
      "Collecting multiprocess>=0.70.16 (from pathos>=0.2.7->causalnex)\n",
      "  Downloading multiprocess-0.70.16-py310-none-any.whl.metadata (7.2 kB)\n",
      "Requirement already satisfied: pyparsing in /usr/lib/python3/dist-packages (from pgmpy<0.1.20,>=0.1.14->causalnex) (3.1.1)\n",
      "Collecting statsmodels (from pgmpy<0.1.20,>=0.1.14->causalnex)\n",
      "  Downloading statsmodels-0.14.2-cp310-cp310-manylinux_2_17_x86_64.manylinux2014_x86_64.whl.metadata (9.2 kB)\n",
      "Collecting tqdm (from pgmpy<0.1.20,>=0.1.14->causalnex)\n",
      "  Using cached tqdm-4.66.4-py3-none-any.whl.metadata (57 kB)\n",
      "Collecting joblib (from pgmpy<0.1.20,>=0.1.14->causalnex)\n",
      "  Using cached joblib-1.4.2-py3-none-any.whl.metadata (5.4 kB)\n",
      "Requirement already satisfied: jinja2>=2.9.6 in /usr/lib/python3/dist-packages (from pyvis>=0.3.2->causalnex) (3.1.2)\n",
      "Collecting jsonpickle>=1.4.1 (from pyvis>=0.3.2->causalnex)\n",
      "  Downloading jsonpickle-3.2.1-py3-none-any.whl.metadata (7.2 kB)\n",
      "Collecting threadpoolctl>=3.1.0 (from scikit-learn>=0.25.0->causalnex)\n",
      "  Using cached threadpoolctl-3.5.0-py3-none-any.whl.metadata (13 kB)\n",
      "Requirement already satisfied: filelock in /usr/lib/python3/dist-packages (from torch>=1.7->causalnex) (3.13.1)\n",
      "Requirement already satisfied: sympy in /usr/lib/python3/dist-packages (from torch>=1.7->causalnex) (1.12)\n",
      "Collecting fsspec (from torch>=1.7->causalnex)\n",
      "  Using cached fsspec-2024.6.0-py3-none-any.whl.metadata (11 kB)\n",
      "Collecting nvidia-cuda-nvrtc-cu12==12.1.105 (from torch>=1.7->causalnex)\n",
      "  Using cached nvidia_cuda_nvrtc_cu12-12.1.105-py3-none-manylinux1_x86_64.whl.metadata (1.5 kB)\n",
      "Collecting nvidia-cuda-runtime-cu12==12.1.105 (from torch>=1.7->causalnex)\n",
      "  Using cached nvidia_cuda_runtime_cu12-12.1.105-py3-none-manylinux1_x86_64.whl.metadata (1.5 kB)\n",
      "Collecting nvidia-cuda-cupti-cu12==12.1.105 (from torch>=1.7->causalnex)\n",
      "  Using cached nvidia_cuda_cupti_cu12-12.1.105-py3-none-manylinux1_x86_64.whl.metadata (1.6 kB)\n",
      "Collecting nvidia-cudnn-cu12==8.9.2.26 (from torch>=1.7->causalnex)\n",
      "  Using cached nvidia_cudnn_cu12-8.9.2.26-py3-none-manylinux1_x86_64.whl.metadata (1.6 kB)\n",
      "Collecting nvidia-cublas-cu12==12.1.3.1 (from torch>=1.7->causalnex)\n",
      "  Using cached nvidia_cublas_cu12-12.1.3.1-py3-none-manylinux1_x86_64.whl.metadata (1.5 kB)\n",
      "Collecting nvidia-cufft-cu12==11.0.2.54 (from torch>=1.7->causalnex)\n",
      "  Using cached nvidia_cufft_cu12-11.0.2.54-py3-none-manylinux1_x86_64.whl.metadata (1.5 kB)\n",
      "Collecting nvidia-curand-cu12==10.3.2.106 (from torch>=1.7->causalnex)\n",
      "  Using cached nvidia_curand_cu12-10.3.2.106-py3-none-manylinux1_x86_64.whl.metadata (1.5 kB)\n",
      "Collecting nvidia-cusolver-cu12==11.4.5.107 (from torch>=1.7->causalnex)\n",
      "  Using cached nvidia_cusolver_cu12-11.4.5.107-py3-none-manylinux1_x86_64.whl.metadata (1.6 kB)\n",
      "Collecting nvidia-cusparse-cu12==12.1.0.106 (from torch>=1.7->causalnex)\n",
      "  Using cached nvidia_cusparse_cu12-12.1.0.106-py3-none-manylinux1_x86_64.whl.metadata (1.6 kB)\n",
      "Collecting nvidia-nccl-cu12==2.20.5 (from torch>=1.7->causalnex)\n",
      "  Using cached nvidia_nccl_cu12-2.20.5-py3-none-manylinux2014_x86_64.whl.metadata (1.8 kB)\n",
      "Collecting nvidia-nvtx-cu12==12.1.105 (from torch>=1.7->causalnex)\n",
      "  Using cached nvidia_nvtx_cu12-12.1.105-py3-none-manylinux1_x86_64.whl.metadata (1.7 kB)\n",
      "Collecting triton==2.3.1 (from torch>=1.7->causalnex)\n",
      "  Downloading triton-2.3.1-cp310-cp310-manylinux_2_17_x86_64.manylinux2014_x86_64.whl.metadata (1.4 kB)\n",
      "Collecting nvidia-nvjitlink-cu12 (from nvidia-cusolver-cu12==11.4.5.107->torch>=1.7->causalnex)\n",
      "  Using cached nvidia_nvjitlink_cu12-12.5.40-py3-none-manylinux2014_x86_64.whl.metadata (1.5 kB)\n",
      "Requirement already satisfied: parso<0.9.0,>=0.8.3 in /home/tema/.local/lib/python3.10/site-packages (from jedi>=0.16->ipython>=8.10.0->causalnex) (0.8.4)\n",
      "Requirement already satisfied: ptyprocess>=0.5 in /home/tema/.local/lib/python3.10/site-packages (from pexpect>4.3->ipython>=8.10.0->causalnex) (0.7.0)\n",
      "Requirement already satisfied: wcwidth in /home/tema/.local/lib/python3.10/site-packages (from prompt-toolkit<3.1.0,>=3.0.41->ipython>=8.10.0->causalnex) (0.2.13)\n",
      "Requirement already satisfied: six>=1.5 in /home/tema/.local/lib/python3.10/site-packages (from python-dateutil>=2.8.1->pandas<2.0,>=1.0->causalnex) (1.16.0)\n",
      "Requirement already satisfied: executing>=1.2.0 in /home/tema/.local/lib/python3.10/site-packages (from stack-data->ipython>=8.10.0->causalnex) (2.0.1)\n",
      "Requirement already satisfied: asttokens>=2.1.0 in /home/tema/.local/lib/python3.10/site-packages (from stack-data->ipython>=8.10.0->causalnex) (2.4.1)\n",
      "Requirement already satisfied: pure-eval in /home/tema/.local/lib/python3.10/site-packages (from stack-data->ipython>=8.10.0->causalnex) (0.2.2)\n",
      "Collecting patsy>=0.5.6 (from statsmodels->pgmpy<0.1.20,>=0.1.14->causalnex)\n",
      "  Downloading patsy-0.5.6-py2.py3-none-any.whl.metadata (3.5 kB)\n",
      "Requirement already satisfied: packaging>=21.3 in /home/tema/.local/lib/python3.10/site-packages (from statsmodels->pgmpy<0.1.20,>=0.1.14->causalnex) (24.1)\n",
      "Downloading causalnex-0.12.1-py3-none-any.whl (153 kB)\n",
      "\u001b[2K   \u001b[90m━━━━━━━━━━━━━━━━━━━━━━━━━━━━━━━━━━━━━━━\u001b[0m \u001b[32m153.9/153.9 kB\u001b[0m \u001b[31m510.4 kB/s\u001b[0m eta \u001b[36m0:00:00\u001b[0ma \u001b[36m0:00:01\u001b[0m\n",
      "\u001b[?25hUsing cached networkx-3.3-py3-none-any.whl (1.7 MB)\n",
      "Downloading numpy-1.23.5-cp310-cp310-manylinux_2_17_x86_64.manylinux2014_x86_64.whl (17.1 MB)\n",
      "\u001b[2K   \u001b[91m━━━━━\u001b[0m\u001b[91m╸\u001b[0m\u001b[90m━━━━━━━━━━━━━━━━━━━━━━━━━━━━━━━━━━\u001b[0m \u001b[32m2.4/17.1 MB\u001b[0m \u001b[31m3.7 kB/s\u001b[0m eta \u001b[36m1:05:14\u001b[0mmm\n",
      "\u001b[?25h\u001b[31mERROR: Exception:\n",
      "Traceback (most recent call last):\n",
      "  File \"/usr/lib/python3/dist-packages/pip/_vendor/urllib3/response.py\", line 438, in _error_catcher\n",
      "    yield\n",
      "  File \"/usr/lib/python3/dist-packages/pip/_vendor/urllib3/response.py\", line 561, in read\n",
      "    data = self._fp_read(amt) if not fp_closed else b\"\"\n",
      "  File \"/usr/lib/python3/dist-packages/pip/_vendor/urllib3/response.py\", line 527, in _fp_read\n",
      "    return self._fp.read(amt) if amt is not None else self._fp.read()\n",
      "  File \"/usr/lib/python3/dist-packages/pip/_vendor/cachecontrol/filewrapper.py\", line 98, in read\n",
      "    data: bytes = self.__fp.read(amt)\n",
      "  File \"/usr/lib/python3.10/http/client.py\", line 466, in read\n",
      "    s = self.fp.read(amt)\n",
      "  File \"/usr/lib/python3.10/socket.py\", line 705, in readinto\n",
      "    return self._sock.recv_into(b)\n",
      "  File \"/usr/lib/python3.10/ssl.py\", line 1307, in recv_into\n",
      "    return self.read(nbytes, buffer)\n",
      "  File \"/usr/lib/python3.10/ssl.py\", line 1163, in read\n",
      "    return self._sslobj.read(len, buffer)\n",
      "TimeoutError: The read operation timed out\n",
      "\n",
      "During handling of the above exception, another exception occurred:\n",
      "\n",
      "Traceback (most recent call last):\n",
      "  File \"/usr/lib/python3/dist-packages/pip/_internal/cli/base_command.py\", line 180, in exc_logging_wrapper\n",
      "    status = run_func(*args)\n",
      "  File \"/usr/lib/python3/dist-packages/pip/_internal/cli/req_command.py\", line 245, in wrapper\n",
      "    return func(self, options, args)\n",
      "  File \"/usr/lib/python3/dist-packages/pip/_internal/commands/install.py\", line 377, in run\n",
      "    requirement_set = resolver.resolve(\n",
      "  File \"/usr/lib/python3/dist-packages/pip/_internal/resolution/resolvelib/resolver.py\", line 179, in resolve\n",
      "    self.factory.preparer.prepare_linked_requirements_more(reqs)\n",
      "  File \"/usr/lib/python3/dist-packages/pip/_internal/operations/prepare.py\", line 552, in prepare_linked_requirements_more\n",
      "    self._complete_partial_requirements(\n",
      "  File \"/usr/lib/python3/dist-packages/pip/_internal/operations/prepare.py\", line 467, in _complete_partial_requirements\n",
      "    for link, (filepath, _) in batch_download:\n",
      "  File \"/usr/lib/python3/dist-packages/pip/_internal/network/download.py\", line 183, in __call__\n",
      "    for chunk in chunks:\n",
      "  File \"/usr/lib/python3/dist-packages/pip/_internal/cli/progress_bars.py\", line 53, in _rich_progress_bar\n",
      "    for chunk in iterable:\n",
      "  File \"/usr/lib/python3/dist-packages/pip/_internal/network/utils.py\", line 63, in response_chunks\n",
      "    for chunk in response.raw.stream(\n",
      "  File \"/usr/lib/python3/dist-packages/pip/_vendor/urllib3/response.py\", line 622, in stream\n",
      "    data = self.read(amt=amt, decode_content=decode_content)\n",
      "  File \"/usr/lib/python3/dist-packages/pip/_vendor/urllib3/response.py\", line 560, in read\n",
      "    with self._error_catcher():\n",
      "  File \"/usr/lib/python3.10/contextlib.py\", line 153, in __exit__\n",
      "    self.gen.throw(typ, value, traceback)\n",
      "  File \"/usr/lib/python3/dist-packages/pip/_vendor/urllib3/response.py\", line 443, in _error_catcher\n",
      "    raise ReadTimeoutError(self._pool, None, \"Read timed out.\")\n",
      "pip._vendor.urllib3.exceptions.ReadTimeoutError: HTTPSConnectionPool(host='files.pythonhosted.org', port=443): Read timed out.\u001b[0m\u001b[31m\n",
      "\u001b[0mNote: you may need to restart the kernel to use updated packages.\n"
     ]
    }
   ],
   "source": [
    "pip install causalnex"
   ]
  },
  {
   "cell_type": "code",
   "execution_count": 6,
   "metadata": {},
   "outputs": [
    {
     "name": "stdout",
     "output_type": "stream",
     "text": [
      "Defaulting to user installation because normal site-packages is not writeable\n",
      "Collecting pandas\n",
      "  Using cached pandas-2.2.2-cp310-cp310-manylinux_2_17_x86_64.manylinux2014_x86_64.whl.metadata (19 kB)\n",
      "Requirement already satisfied: numpy>=1.22.4 in /usr/lib/python3/dist-packages (from pandas) (1.26.4)\n",
      "Requirement already satisfied: python-dateutil>=2.8.2 in /home/tema/.local/lib/python3.10/site-packages (from pandas) (2.9.0.post0)\n",
      "Requirement already satisfied: pytz>=2020.1 in /usr/lib/python3/dist-packages (from pandas) (2024.1)\n",
      "Collecting tzdata>=2022.7 (from pandas)\n",
      "  Using cached tzdata-2024.1-py2.py3-none-any.whl.metadata (1.4 kB)\n",
      "Requirement already satisfied: six>=1.5 in /home/tema/.local/lib/python3.10/site-packages (from python-dateutil>=2.8.2->pandas) (1.16.0)\n",
      "Downloading pandas-2.2.2-cp310-cp310-manylinux_2_17_x86_64.manylinux2014_x86_64.whl (13.0 MB)\n",
      "\u001b[2K   \u001b[90m━━━━━━━━━━━━━━━━━━━━━━━━━━━━━━━━━━━━━━━━\u001b[0m \u001b[32m13.0/13.0 MB\u001b[0m \u001b[31m281.9 kB/s\u001b[0m eta \u001b[36m0:00:00\u001b[0m00:01\u001b[0m00:02\u001b[0m\n",
      "\u001b[?25hUsing cached tzdata-2024.1-py2.py3-none-any.whl (345 kB)\n",
      "Installing collected packages: tzdata, pandas\n",
      "Successfully installed pandas-2.2.2 tzdata-2024.1\n",
      "Note: you may need to restart the kernel to use updated packages.\n"
     ]
    }
   ],
   "source": [
    "pip install pandas\n"
   ]
  },
  {
   "cell_type": "code",
   "execution_count": 10,
   "metadata": {},
   "outputs": [
    {
     "name": "stdout",
     "output_type": "stream",
     "text": [
      "Defaulting to user installation because normal site-packages is not writeable\n",
      "Requirement already satisfied: numpy in /usr/lib/python3/dist-packages (1.26.4)\n",
      "Note: you may need to restart the kernel to use updated packages.\n"
     ]
    }
   ],
   "source": [
    "pip install numpy"
   ]
  },
  {
   "cell_type": "code",
   "execution_count": 9,
   "metadata": {},
   "outputs": [
    {
     "ename": "ImportError",
     "evalue": "Unable to import required dependencies:\nnumpy: Error importing numpy: you should not try to import numpy from\n        its source directory; please exit the numpy source tree, and relaunch\n        your python interpreter from there.",
     "output_type": "error",
     "traceback": [
      "\u001b[0;31m---------------------------------------------------------------------------\u001b[0m",
      "\u001b[0;31mImportError\u001b[0m                               Traceback (most recent call last)",
      "Cell \u001b[0;32mIn[9], line 1\u001b[0m\n\u001b[0;32m----> 1\u001b[0m \u001b[38;5;28;01mimport\u001b[39;00m \u001b[38;5;21;01mpandas\u001b[39;00m \u001b[38;5;28;01mas\u001b[39;00m \u001b[38;5;21;01mpd\u001b[39;00m\n\u001b[1;32m      2\u001b[0m \u001b[38;5;28;01mimport\u001b[39;00m \u001b[38;5;21;01msys\u001b[39;00m\u001b[38;5;241m,\u001b[39m \u001b[38;5;21;01mos\u001b[39;00m\n\u001b[1;32m      3\u001b[0m \u001b[38;5;28;01mimport\u001b[39;00m \u001b[38;5;21;01mnumpy\u001b[39;00m \u001b[38;5;28;01mas\u001b[39;00m \u001b[38;5;21;01mnp\u001b[39;00m\n",
      "File \u001b[0;32m~/.local/lib/python3.10/site-packages/pandas/__init__.py:19\u001b[0m\n\u001b[1;32m     16\u001b[0m         _missing_dependencies\u001b[38;5;241m.\u001b[39mappend(\u001b[38;5;124mf\u001b[39m\u001b[38;5;124m\"\u001b[39m\u001b[38;5;132;01m{\u001b[39;00m_dependency\u001b[38;5;132;01m}\u001b[39;00m\u001b[38;5;124m: \u001b[39m\u001b[38;5;132;01m{\u001b[39;00m_e\u001b[38;5;132;01m}\u001b[39;00m\u001b[38;5;124m\"\u001b[39m)\n\u001b[1;32m     18\u001b[0m \u001b[38;5;28;01mif\u001b[39;00m _missing_dependencies:  \u001b[38;5;66;03m# pragma: no cover\u001b[39;00m\n\u001b[0;32m---> 19\u001b[0m     \u001b[38;5;28;01mraise\u001b[39;00m \u001b[38;5;167;01mImportError\u001b[39;00m(\n\u001b[1;32m     20\u001b[0m         \u001b[38;5;124m\"\u001b[39m\u001b[38;5;124mUnable to import required dependencies:\u001b[39m\u001b[38;5;130;01m\\n\u001b[39;00m\u001b[38;5;124m\"\u001b[39m \u001b[38;5;241m+\u001b[39m \u001b[38;5;124m\"\u001b[39m\u001b[38;5;130;01m\\n\u001b[39;00m\u001b[38;5;124m\"\u001b[39m\u001b[38;5;241m.\u001b[39mjoin(_missing_dependencies)\n\u001b[1;32m     21\u001b[0m     )\n\u001b[1;32m     22\u001b[0m \u001b[38;5;28;01mdel\u001b[39;00m _hard_dependencies, _dependency, _missing_dependencies\n\u001b[1;32m     24\u001b[0m \u001b[38;5;28;01mtry\u001b[39;00m:\n\u001b[1;32m     25\u001b[0m     \u001b[38;5;66;03m# numpy compat\u001b[39;00m\n",
      "\u001b[0;31mImportError\u001b[0m: Unable to import required dependencies:\nnumpy: Error importing numpy: you should not try to import numpy from\n        its source directory; please exit the numpy source tree, and relaunch\n        your python interpreter from there."
     ]
    }
   ],
   "source": [
    "import pandas as pd\n",
    "import sys, os\n",
    "import numpy as np\n",
    "\n",
    "from causalnex.structure import StructureModel\n",
    "from causalnex.structure.notears import from_pandas\n",
    "\n",
    "\n",
    "sys.path.append(os.path.abspath(os.path.join('../scripts')))\n",
    "\n",
    "from causalnex.structure import StructureModel\n",
    "\n",
    "#from eda_pipeline import EDAPipeline\n",
    "#from causal_learning_helper import CausalHelper"
   ]
  },
  {
   "cell_type": "code",
   "execution_count": null,
   "metadata": {},
   "outputs": [],
   "source": []
  },
  {
   "cell_type": "code",
   "execution_count": null,
   "metadata": {},
   "outputs": [],
   "source": [
    "import warnings\n",
    "from causalnex.structure import StructureModel\n",
    "\n",
    "#creating empty structure model\n",
    "warnings.filterwarnings(\"ignore\")  # silence warnings\n",
    "\n",
    "sm = StructureModel()"
   ]
  },
  {
   "cell_type": "code",
   "execution_count": null,
   "metadata": {},
   "outputs": [],
   "source": [
    "#relationships between features\n"
   ]
  }
 ],
 "metadata": {
  "kernelspec": {
   "display_name": "Lenv",
   "language": "python",
   "name": "python3"
  },
  "language_info": {
   "codemirror_mode": {
    "name": "ipython",
    "version": 3
   },
   "file_extension": ".py",
   "mimetype": "text/x-python",
   "name": "python",
   "nbconvert_exporter": "python",
   "pygments_lexer": "ipython3",
   "version": "3.10.14"
  }
 },
 "nbformat": 4,
 "nbformat_minor": 2
}
